<?xml version="1.0" ?>
<robot name="vac" xmlns:xacro="http://www.ros.org/wiki/xacro">

<xacro:include filename="$(find vac_description)/urdf/materials.xacro" />
<xacro:include filename="$(find vac_description)/urdf/vac.trans" />
<xacro:include filename="$(find vac_description)/urdf/vac.gazebo" />
<link name="base_link">
  <inertial>
    <origin rpy="0 0 0" xyz="0.001915260398445279 0.0 0.018522278568649287"/>
    <mass value="0.11912938572725087"/>
    <inertia ixx="5.7e-05" ixy="-0.0" ixz="3e-06" iyy="0.000145" iyz="-0.0" izz="0.000198"/>
  </inertial>
  <visual>
    <origin rpy="0 0 0" xyz="0 0 0"/>
    <geometry>
      <mesh filename="package://vac_description/meshes/base_link.stl" scale="0.001 0.001 0.001"/>
    </geometry>
    <material name="silver"/>
  </visual>
  <collision>
    <origin rpy="0 0 0" xyz="0 0 0"/>
    <geometry>
      <mesh filename="package://vac_description/meshes/base_link.stl" scale="0.001 0.001 0.001"/>
    </geometry>
  </collision>
</link>

<link name="r_wheel_1">
  <inertial>
    <origin rpy="0 0 0" xyz="4.4703453092043155e-10 -0.009999999999999988 -5.5879349758480856e-11"/>
    <mass value="0.019940473970497814"/>
    <inertia ixx="2e-06" ixy="-0.0" ixz="0.0" iyy="3e-06" iyz="0.0" izz="2e-06"/>
  </inertial>
  <visual>
    <origin rpy="0 0 0" xyz="0.02 0.035 -0.0025"/>
    <geometry>
      <mesh filename="package://vac_description/meshes/r_wheel_1.stl" scale="0.001 0.001 0.001"/>
    </geometry>
    <material name="silver"/>
  </visual>
  <collision>
    <origin rpy="0 0 0" xyz="0.02 0.035 -0.0025"/>
    <geometry>
      <mesh filename="package://vac_description/meshes/r_wheel_1.stl" scale="0.001 0.001 0.001"/>
    </geometry>
  </collision>
</link>

<joint name="r_joint" type="continuous">
  <origin rpy="0 0 0" xyz="-0.02 -0.035 0.0025"/>
  <parent link="base_link"/>
  <child link="r_wheel_1"/>
  <axis xyz="0.0 1.0 0.0"/>
</joint>

<link name="l_wheel_1">
  <inertial>
    <origin rpy="0 0 0" xyz="4.4703453092043155e-10 0.009999999999999988 -5.5879349758480856e-11"/>
    <mass value="0.019940473970497814"/>
    <inertia ixx="2e-06" ixy="0.0" ixz="0.0" iyy="3e-06" iyz="-0.0" izz="2e-06"/>
  </inertial>
  <visual>
    <origin rpy="0 0 0" xyz="0.02 -0.035 -0.0025"/>
    <geometry>
      <mesh filename="package://vac_description/meshes/l_wheel_1.stl" scale="0.001 0.001 0.001"/>
    </geometry>
    <material name="silver"/>
  </visual>
  <collision>
    <origin rpy="0 0 0" xyz="0.02 -0.035 -0.0025"/>
    <geometry>
      <mesh filename="package://vac_description/meshes/l_wheel_1.stl" scale="0.001 0.001 0.001"/>
    </geometry>
  </collision>
</link>

<joint name="l_joint" type="continuous">
  <origin rpy="0 0 0" xyz="-0.02 0.035 0.0025"/>
  <parent link="base_link"/>
  <child link="l_wheel_1"/>
  <axis xyz="0.0 1.0 0.0"/>
</joint>



<link name="upper_plate_1">
  <inertial>
    <origin rpy="0 0 0" xyz="0.043126318713498396 0.029906839251503375 -0.0070827454590651"/>
    <mass value="0.1446581252670634"/>
    <inertia ixx="6.1e-05" ixy="-0.0" ixz="5e-06" iyy="0.000115" iyz="0.0" izz="0.000163"/>
  </inertial>
  <visual>
    <origin rpy="0 0 0" xyz="0.05 0.03 -0.059"/>
    <geometry>
      <mesh filename="package://vac_description/meshes/upper_plate_1.stl" scale="0.001 0.001 0.001"/>
    </geometry>
    <material name="silver"/>
  </visual>
  <collision>
    <origin rpy="0 0 0" xyz="0.05 0.03 -0.059"/>
    <geometry>
      <mesh filename="package://vac_description/meshes/upper_plate_1.stl" scale="0.001 0.001 0.001"/>
    </geometry>
  </collision>
</link>

<joint name="rb" type="fixed">
  <origin rpy="0 0 0" xyz="-0.05 -0.03 0.059"/>
  <parent link="base_link"/>
  <child link="upper_plate_1"/>
</joint>

</robot>
